[2024-04-30T20:21:43.675+0000] {taskinstance.py:1979} INFO - Dependencies all met for dep_context=non-requeueable deps ti=<TaskInstance: homework2_data_pipeline_demo.data_acquisition manual__2024-04-30T19:51:15.036853+00:00 [queued]>
[2024-04-30T20:21:43.688+0000] {taskinstance.py:1979} INFO - Dependencies all met for dep_context=requeueable deps ti=<TaskInstance: homework2_data_pipeline_demo.data_acquisition manual__2024-04-30T19:51:15.036853+00:00 [queued]>
[2024-04-30T20:21:43.689+0000] {taskinstance.py:2193} INFO - Starting attempt 2 of 2
[2024-04-30T20:21:43.707+0000] {taskinstance.py:2217} INFO - Executing <Task(_PythonVirtualenvDecoratedOperator): data_acquisition> on 2024-04-30 19:51:15.036853+00:00
[2024-04-30T20:21:43.714+0000] {standard_task_runner.py:60} INFO - Started process 4762 to run task
[2024-04-30T20:21:43.719+0000] {standard_task_runner.py:87} INFO - Running: ['***', 'tasks', 'run', 'homework2_data_pipeline_demo', 'data_acquisition', 'manual__2024-04-30T19:51:15.036853+00:00', '--job-id', '23', '--raw', '--subdir', 'DAGS_FOLDER/Hw2.py', '--cfg-path', '/tmp/tmpjeal3mm3']
[2024-04-30T20:21:43.721+0000] {standard_task_runner.py:88} INFO - Job 23: Subtask data_acquisition
[2024-04-30T20:21:43.787+0000] {task_command.py:423} INFO - Running <TaskInstance: homework2_data_pipeline_demo.data_acquisition manual__2024-04-30T19:51:15.036853+00:00 [running]> on host f153e58ecd1c
[2024-04-30T20:21:43.890+0000] {taskinstance.py:2513} INFO - Exporting env vars: AIRFLOW_CTX_DAG_OWNER='***' AIRFLOW_CTX_DAG_ID='homework2_data_pipeline_demo' AIRFLOW_CTX_TASK_ID='data_acquisition' AIRFLOW_CTX_EXECUTION_DATE='2024-04-30T19:51:15.036853+00:00' AIRFLOW_CTX_TRY_NUMBER='2' AIRFLOW_CTX_DAG_RUN_ID='manual__2024-04-30T19:51:15.036853+00:00'
[2024-04-30T20:21:43.893+0000] {process_utils.py:182} INFO - Executing cmd: /usr/local/bin/python -m virtualenv /tmp/venvmlhij1fn --python=python
[2024-04-30T20:21:43.906+0000] {process_utils.py:186} INFO - Output:
[2024-04-30T20:21:45.028+0000] {process_utils.py:190} INFO - created virtual environment CPython3.8.19.final.0-64 in 435ms
[2024-04-30T20:21:45.029+0000] {process_utils.py:190} INFO -   creator CPython3Posix(dest=/tmp/venvmlhij1fn, clear=False, no_vcs_ignore=False, global=False)
[2024-04-30T20:21:45.030+0000] {process_utils.py:190} INFO -   seeder FromAppData(download=False, pip=bundle, setuptools=bundle, wheel=bundle, via=copy, app_data_dir=/home/***/.local/share/virtualenv)
[2024-04-30T20:21:45.030+0000] {process_utils.py:190} INFO -     added seed packages: pip==24.0, setuptools==69.2.0, wheel==0.43.0
[2024-04-30T20:21:45.031+0000] {process_utils.py:190} INFO -   activators BashActivator,CShellActivator,FishActivator,NushellActivator,PowerShellActivator,PythonActivator
[2024-04-30T20:21:45.075+0000] {process_utils.py:182} INFO - Executing cmd: /tmp/venvmlhij1fn/bin/pip install -r /tmp/venvmlhij1fn/requirements.txt
[2024-04-30T20:21:45.088+0000] {process_utils.py:186} INFO - Output:
[2024-04-30T20:21:46.744+0000] {process_utils.py:190} INFO - Collecting dill (from -r /tmp/venvmlhij1fn/requirements.txt (line 1))
[2024-04-30T20:21:46.747+0000] {process_utils.py:190} INFO -   Using cached dill-0.3.8-py3-none-any.whl.metadata (10 kB)
[2024-04-30T20:21:46.784+0000] {process_utils.py:190} INFO - Collecting funcsigs (from -r /tmp/venvmlhij1fn/requirements.txt (line 2))
[2024-04-30T20:21:46.789+0000] {process_utils.py:190} INFO -   Using cached funcsigs-1.0.2-py2.py3-none-any.whl.metadata (14 kB)
[2024-04-30T20:21:46.805+0000] {process_utils.py:190} INFO - Using cached dill-0.3.8-py3-none-any.whl (116 kB)
[2024-04-30T20:21:46.809+0000] {process_utils.py:190} INFO - Using cached funcsigs-1.0.2-py2.py3-none-any.whl (17 kB)
[2024-04-30T20:21:46.942+0000] {process_utils.py:190} INFO - Installing collected packages: funcsigs, dill
[2024-04-30T20:21:47.097+0000] {process_utils.py:190} INFO - Successfully installed dill-0.3.8 funcsigs-1.0.2
[2024-04-30T20:21:47.475+0000] {process_utils.py:182} INFO - Executing cmd: /tmp/venvmlhij1fn/bin/python /tmp/venv-callsncw3k4a/script.py /tmp/venv-callsncw3k4a/script.in /tmp/venv-callsncw3k4a/script.out /tmp/venv-callsncw3k4a/string_args.txt /tmp/venv-callsncw3k4a/termination.log
[2024-04-30T20:21:47.487+0000] {process_utils.py:186} INFO - Output:
[2024-04-30T20:21:47.599+0000] {process_utils.py:190} INFO - Traceback (most recent call last):
[2024-04-30T20:21:47.600+0000] {process_utils.py:190} INFO -   File "/tmp/venv-callsncw3k4a/script.py", line 59, in <module>
[2024-04-30T20:21:47.600+0000] {process_utils.py:190} INFO -     res = data_acquisition(*arg_dict["args"], **arg_dict["kwargs"])
[2024-04-30T20:21:47.601+0000] {process_utils.py:190} INFO -   File "/tmp/venv-callsncw3k4a/script.py", line 25, in data_acquisition
[2024-04-30T20:21:47.602+0000] {process_utils.py:190} INFO -     os.makedirs(os.path.dirname(data_path), exist_ok=True)
[2024-04-30T20:21:47.603+0000] {process_utils.py:190} INFO - NameError: name 'os' is not defined
[2024-04-30T20:21:47.678+0000] {taskinstance.py:2731} ERROR - Task failed with exception
Traceback (most recent call last):
  File "/home/airflow/.local/lib/python3.8/site-packages/airflow/models/taskinstance.py", line 444, in _execute_task
    result = _execute_callable(context=context, **execute_callable_kwargs)
  File "/home/airflow/.local/lib/python3.8/site-packages/airflow/models/taskinstance.py", line 414, in _execute_callable
    return execute_callable(context=context, **execute_callable_kwargs)
  File "/home/airflow/.local/lib/python3.8/site-packages/airflow/decorators/base.py", line 241, in execute
    return_value = super().execute(context)
  File "/home/airflow/.local/lib/python3.8/site-packages/airflow/operators/python.py", line 401, in execute
    return super().execute(context=serializable_context)
  File "/home/airflow/.local/lib/python3.8/site-packages/airflow/operators/python.py", line 200, in execute
    return_value = self.execute_callable()
  File "/home/airflow/.local/lib/python3.8/site-packages/airflow/operators/python.py", line 723, in execute_callable
    result = self._execute_python_callable_in_subprocess(python_path)
  File "/home/airflow/.local/lib/python3.8/site-packages/airflow/operators/python.py", line 478, in _execute_python_callable_in_subprocess
    raise AirflowException(error_msg) from None
airflow.exceptions.AirflowException: Process returned non-zero exit status 1.
name 'os' is not defined
[2024-04-30T20:21:47.683+0000] {taskinstance.py:1149} INFO - Marking task as FAILED. dag_id=homework2_data_pipeline_demo, task_id=data_acquisition, execution_date=20240430T195115, start_date=20240430T202143, end_date=20240430T202147
[2024-04-30T20:21:47.705+0000] {standard_task_runner.py:107} ERROR - Failed to execute job 23 for task data_acquisition (Process returned non-zero exit status 1.
name 'os' is not defined; 4762)
[2024-04-30T20:21:47.747+0000] {local_task_job_runner.py:234} INFO - Task exited with return code 1
[2024-04-30T20:21:47.778+0000] {taskinstance.py:3312} INFO - 0 downstream tasks scheduled from follow-on schedule check
