[2024-04-30T20:08:13.280+0000] {taskinstance.py:1979} INFO - Dependencies all met for dep_context=non-requeueable deps ti=<TaskInstance: homework2_data_pipeline_demo.data_aquisition manual__2024-04-30T19:44:08.862132+00:00 [queued]>
[2024-04-30T20:08:13.291+0000] {taskinstance.py:1979} INFO - Dependencies all met for dep_context=requeueable deps ti=<TaskInstance: homework2_data_pipeline_demo.data_aquisition manual__2024-04-30T19:44:08.862132+00:00 [queued]>
[2024-04-30T20:08:13.292+0000] {taskinstance.py:2193} INFO - Starting attempt 4 of 4
[2024-04-30T20:08:13.309+0000] {taskinstance.py:2217} INFO - Executing <Task(_PythonVirtualenvDecoratedOperator): data_aquisition> on 2024-04-30 19:44:08.862132+00:00
[2024-04-30T20:08:13.316+0000] {standard_task_runner.py:60} INFO - Started process 4471 to run task
[2024-04-30T20:08:13.320+0000] {standard_task_runner.py:87} INFO - Running: ['***', 'tasks', 'run', 'homework2_data_pipeline_demo', 'data_aquisition', 'manual__2024-04-30T19:44:08.862132+00:00', '--job-id', '17', '--raw', '--subdir', 'DAGS_FOLDER/Hw2.py', '--cfg-path', '/tmp/tmp3toci05z']
[2024-04-30T20:08:13.324+0000] {standard_task_runner.py:88} INFO - Job 17: Subtask data_aquisition
[2024-04-30T20:08:13.388+0000] {task_command.py:423} INFO - Running <TaskInstance: homework2_data_pipeline_demo.data_aquisition manual__2024-04-30T19:44:08.862132+00:00 [running]> on host f153e58ecd1c
[2024-04-30T20:08:13.497+0000] {taskinstance.py:2513} INFO - Exporting env vars: AIRFLOW_CTX_DAG_OWNER='***' AIRFLOW_CTX_DAG_ID='homework2_data_pipeline_demo' AIRFLOW_CTX_TASK_ID='data_aquisition' AIRFLOW_CTX_EXECUTION_DATE='2024-04-30T19:44:08.862132+00:00' AIRFLOW_CTX_TRY_NUMBER='4' AIRFLOW_CTX_DAG_RUN_ID='manual__2024-04-30T19:44:08.862132+00:00'
[2024-04-30T20:08:13.501+0000] {process_utils.py:182} INFO - Executing cmd: /usr/local/bin/python -m virtualenv /tmp/venvn3ihmwc6 --python=python
[2024-04-30T20:08:13.516+0000] {process_utils.py:186} INFO - Output:
[2024-04-30T20:08:14.636+0000] {process_utils.py:190} INFO - created virtual environment CPython3.8.19.final.0-64 in 438ms
[2024-04-30T20:08:14.637+0000] {process_utils.py:190} INFO -   creator CPython3Posix(dest=/tmp/venvn3ihmwc6, clear=False, no_vcs_ignore=False, global=False)
[2024-04-30T20:08:14.638+0000] {process_utils.py:190} INFO -   seeder FromAppData(download=False, pip=bundle, setuptools=bundle, wheel=bundle, via=copy, app_data_dir=/home/***/.local/share/virtualenv)
[2024-04-30T20:08:14.639+0000] {process_utils.py:190} INFO -     added seed packages: pip==24.0, setuptools==69.2.0, wheel==0.43.0
[2024-04-30T20:08:14.640+0000] {process_utils.py:190} INFO -   activators BashActivator,CShellActivator,FishActivator,NushellActivator,PowerShellActivator,PythonActivator
[2024-04-30T20:08:14.709+0000] {process_utils.py:182} INFO - Executing cmd: /tmp/venvn3ihmwc6/bin/pip install -r /tmp/venvn3ihmwc6/requirements.txt
[2024-04-30T20:08:14.722+0000] {process_utils.py:186} INFO - Output:
[2024-04-30T20:08:16.299+0000] {process_utils.py:190} INFO - Collecting dill (from -r /tmp/venvn3ihmwc6/requirements.txt (line 1))
[2024-04-30T20:08:16.303+0000] {process_utils.py:190} INFO -   Using cached dill-0.3.8-py3-none-any.whl.metadata (10 kB)
[2024-04-30T20:08:16.338+0000] {process_utils.py:190} INFO - Collecting funcsigs (from -r /tmp/venvn3ihmwc6/requirements.txt (line 2))
[2024-04-30T20:08:16.342+0000] {process_utils.py:190} INFO -   Using cached funcsigs-1.0.2-py2.py3-none-any.whl.metadata (14 kB)
[2024-04-30T20:08:16.355+0000] {process_utils.py:190} INFO - Using cached dill-0.3.8-py3-none-any.whl (116 kB)
[2024-04-30T20:08:16.359+0000] {process_utils.py:190} INFO - Using cached funcsigs-1.0.2-py2.py3-none-any.whl (17 kB)
[2024-04-30T20:08:16.463+0000] {process_utils.py:190} INFO - Installing collected packages: funcsigs, dill
[2024-04-30T20:08:16.606+0000] {process_utils.py:190} INFO - Successfully installed dill-0.3.8 funcsigs-1.0.2
[2024-04-30T20:08:16.930+0000] {process_utils.py:182} INFO - Executing cmd: /tmp/venvn3ihmwc6/bin/python /tmp/venv-callb11_gv2x/script.py /tmp/venv-callb11_gv2x/script.in /tmp/venv-callb11_gv2x/script.out /tmp/venv-callb11_gv2x/string_args.txt /tmp/venv-callb11_gv2x/termination.log
[2024-04-30T20:08:16.940+0000] {process_utils.py:186} INFO - Output:
[2024-04-30T20:08:17.043+0000] {process_utils.py:190} INFO - Traceback (most recent call last):
[2024-04-30T20:08:17.044+0000] {process_utils.py:190} INFO -   File "/tmp/venv-callb11_gv2x/script.py", line 73, in <module>
[2024-04-30T20:08:17.045+0000] {process_utils.py:190} INFO -     res = data_aquisition(*arg_dict["args"], **arg_dict["kwargs"])
[2024-04-30T20:08:17.045+0000] {process_utils.py:190} INFO -   File "/tmp/venv-callb11_gv2x/script.py", line 23, in data_aquisition
[2024-04-30T20:08:17.046+0000] {process_utils.py:190} INFO -     import pandas as pd
[2024-04-30T20:08:17.046+0000] {process_utils.py:190} INFO - ModuleNotFoundError: No module named 'pandas'
[2024-04-30T20:08:17.112+0000] {taskinstance.py:2731} ERROR - Task failed with exception
Traceback (most recent call last):
  File "/home/airflow/.local/lib/python3.8/site-packages/airflow/models/taskinstance.py", line 444, in _execute_task
    result = _execute_callable(context=context, **execute_callable_kwargs)
  File "/home/airflow/.local/lib/python3.8/site-packages/airflow/models/taskinstance.py", line 414, in _execute_callable
    return execute_callable(context=context, **execute_callable_kwargs)
  File "/home/airflow/.local/lib/python3.8/site-packages/airflow/decorators/base.py", line 241, in execute
    return_value = super().execute(context)
  File "/home/airflow/.local/lib/python3.8/site-packages/airflow/operators/python.py", line 401, in execute
    return super().execute(context=serializable_context)
  File "/home/airflow/.local/lib/python3.8/site-packages/airflow/operators/python.py", line 200, in execute
    return_value = self.execute_callable()
  File "/home/airflow/.local/lib/python3.8/site-packages/airflow/operators/python.py", line 723, in execute_callable
    result = self._execute_python_callable_in_subprocess(python_path)
  File "/home/airflow/.local/lib/python3.8/site-packages/airflow/operators/python.py", line 478, in _execute_python_callable_in_subprocess
    raise AirflowException(error_msg) from None
airflow.exceptions.AirflowException: Process returned non-zero exit status 1.
No module named 'pandas'
[2024-04-30T20:08:17.118+0000] {taskinstance.py:1149} INFO - Marking task as FAILED. dag_id=homework2_data_pipeline_demo, task_id=data_aquisition, execution_date=20240430T194408, start_date=20240430T200813, end_date=20240430T200817
[2024-04-30T20:08:17.137+0000] {standard_task_runner.py:107} ERROR - Failed to execute job 17 for task data_aquisition (Process returned non-zero exit status 1.
No module named 'pandas'; 4471)
[2024-04-30T20:08:17.148+0000] {local_task_job_runner.py:234} INFO - Task exited with return code 1
[2024-04-30T20:08:17.178+0000] {taskinstance.py:3312} INFO - 0 downstream tasks scheduled from follow-on schedule check
