[2024-05-01T06:53:49.824+0000] {taskinstance.py:1979} INFO - Dependencies all met for dep_context=non-requeueable deps ti=<TaskInstance: homework2_data_pipeline_demo.data_cleanse manual__2024-04-30T20:55:43.518367+00:00 [queued]>
[2024-05-01T06:53:49.839+0000] {taskinstance.py:1979} INFO - Dependencies all met for dep_context=requeueable deps ti=<TaskInstance: homework2_data_pipeline_demo.data_cleanse manual__2024-04-30T20:55:43.518367+00:00 [queued]>
[2024-05-01T06:53:49.840+0000] {taskinstance.py:2193} INFO - Starting attempt 12 of 12
[2024-05-01T06:53:49.859+0000] {taskinstance.py:2217} INFO - Executing <Task(_PythonDecoratedOperator): data_cleanse> on 2024-04-30 20:55:43.518367+00:00
[2024-05-01T06:53:49.866+0000] {standard_task_runner.py:60} INFO - Started process 7917 to run task
[2024-05-01T06:53:49.872+0000] {standard_task_runner.py:87} INFO - Running: ['***', 'tasks', 'run', 'homework2_data_pipeline_demo', 'data_cleanse', 'manual__2024-04-30T20:55:43.518367+00:00', '--job-id', '91', '--raw', '--subdir', 'DAGS_FOLDER/pipeline.py', '--cfg-path', '/tmp/tmpltjpmkg8']
[2024-05-01T06:53:49.874+0000] {standard_task_runner.py:88} INFO - Job 91: Subtask data_cleanse
[2024-05-01T06:53:49.947+0000] {task_command.py:423} INFO - Running <TaskInstance: homework2_data_pipeline_demo.data_cleanse manual__2024-04-30T20:55:43.518367+00:00 [running]> on host f153e58ecd1c
[2024-05-01T06:53:50.066+0000] {taskinstance.py:2513} INFO - Exporting env vars: AIRFLOW_CTX_DAG_OWNER='***' AIRFLOW_CTX_DAG_ID='homework2_data_pipeline_demo' AIRFLOW_CTX_TASK_ID='data_cleanse' AIRFLOW_CTX_EXECUTION_DATE='2024-04-30T20:55:43.518367+00:00' AIRFLOW_CTX_TRY_NUMBER='12' AIRFLOW_CTX_DAG_RUN_ID='manual__2024-04-30T20:55:43.518367+00:00'
[2024-05-01T06:53:50.081+0000] {taskinstance.py:2731} ERROR - Task failed with exception
Traceback (most recent call last):
  File "/home/airflow/.local/lib/python3.8/site-packages/pandas/core/indexes/base.py", line 3653, in get_loc
    return self._engine.get_loc(casted_key)
  File "pandas/_libs/index.pyx", line 147, in pandas._libs.index.IndexEngine.get_loc
  File "pandas/_libs/index.pyx", line 176, in pandas._libs.index.IndexEngine.get_loc
  File "pandas/_libs/hashtable_class_helper.pxi", line 7080, in pandas._libs.hashtable.PyObjectHashTable.get_item
  File "pandas/_libs/hashtable_class_helper.pxi", line 7088, in pandas._libs.hashtable.PyObjectHashTable.get_item
KeyError: 'StateName'

The above exception was the direct cause of the following exception:

Traceback (most recent call last):
  File "/home/airflow/.local/lib/python3.8/site-packages/airflow/models/taskinstance.py", line 444, in _execute_task
    result = _execute_callable(context=context, **execute_callable_kwargs)
  File "/home/airflow/.local/lib/python3.8/site-packages/airflow/models/taskinstance.py", line 414, in _execute_callable
    return execute_callable(context=context, **execute_callable_kwargs)
  File "/home/airflow/.local/lib/python3.8/site-packages/airflow/decorators/base.py", line 241, in execute
    return_value = super().execute(context)
  File "/home/airflow/.local/lib/python3.8/site-packages/airflow/operators/python.py", line 200, in execute
    return_value = self.execute_callable()
  File "/home/airflow/.local/lib/python3.8/site-packages/airflow/operators/python.py", line 217, in execute_callable
    return self.python_callable(*self.op_args, **self.op_kwargs)
  File "/opt/airflow/dags/pipeline.py", line 67, in data_cleanse
    df = df[df['StateName'].str.contains('CA', na=False)]
  File "/home/airflow/.local/lib/python3.8/site-packages/pandas/core/frame.py", line 3761, in __getitem__
    indexer = self.columns.get_loc(key)
  File "/home/airflow/.local/lib/python3.8/site-packages/pandas/core/indexes/base.py", line 3655, in get_loc
    raise KeyError(key) from err
KeyError: 'StateName'
[2024-05-01T06:53:50.099+0000] {taskinstance.py:1149} INFO - Marking task as FAILED. dag_id=homework2_data_pipeline_demo, task_id=data_cleanse, execution_date=20240430T205543, start_date=20240501T065349, end_date=20240501T065350
[2024-05-01T06:53:50.116+0000] {standard_task_runner.py:107} ERROR - Failed to execute job 91 for task data_cleanse ('StateName'; 7917)
[2024-05-01T06:53:50.166+0000] {local_task_job_runner.py:234} INFO - Task exited with return code 1
[2024-05-01T06:53:50.197+0000] {taskinstance.py:3312} INFO - 0 downstream tasks scheduled from follow-on schedule check
