[2024-05-01T06:57:48.932+0000] {taskinstance.py:1979} INFO - Dependencies all met for dep_context=non-requeueable deps ti=<TaskInstance: homework2_data_pipeline_demo.data_cleanse manual__2024-04-30T20:55:43.518367+00:00 [queued]>
[2024-05-01T06:57:48.945+0000] {taskinstance.py:1979} INFO - Dependencies all met for dep_context=requeueable deps ti=<TaskInstance: homework2_data_pipeline_demo.data_cleanse manual__2024-04-30T20:55:43.518367+00:00 [queued]>
[2024-05-01T06:57:48.946+0000] {taskinstance.py:2193} INFO - Starting attempt 14 of 14
[2024-05-01T06:57:48.964+0000] {taskinstance.py:2217} INFO - Executing <Task(_PythonDecoratedOperator): data_cleanse> on 2024-04-30 20:55:43.518367+00:00
[2024-05-01T06:57:48.972+0000] {standard_task_runner.py:60} INFO - Started process 8071 to run task
[2024-05-01T06:57:48.977+0000] {standard_task_runner.py:87} INFO - Running: ['***', 'tasks', 'run', 'homework2_data_pipeline_demo', 'data_cleanse', 'manual__2024-04-30T20:55:43.518367+00:00', '--job-id', '95', '--raw', '--subdir', 'DAGS_FOLDER/pipeline.py', '--cfg-path', '/tmp/tmpdgsi8nh_']
[2024-05-01T06:57:48.980+0000] {standard_task_runner.py:88} INFO - Job 95: Subtask data_cleanse
[2024-05-01T06:57:49.049+0000] {task_command.py:423} INFO - Running <TaskInstance: homework2_data_pipeline_demo.data_cleanse manual__2024-04-30T20:55:43.518367+00:00 [running]> on host f153e58ecd1c
[2024-05-01T06:57:49.169+0000] {taskinstance.py:2513} INFO - Exporting env vars: AIRFLOW_CTX_DAG_OWNER='***' AIRFLOW_CTX_DAG_ID='homework2_data_pipeline_demo' AIRFLOW_CTX_TASK_ID='data_cleanse' AIRFLOW_CTX_EXECUTION_DATE='2024-04-30T20:55:43.518367+00:00' AIRFLOW_CTX_TRY_NUMBER='14' AIRFLOW_CTX_DAG_RUN_ID='manual__2024-04-30T20:55:43.518367+00:00'
[2024-05-01T06:57:49.175+0000] {taskinstance.py:2731} ERROR - Task failed with exception
Traceback (most recent call last):
  File "/home/airflow/.local/lib/python3.8/site-packages/airflow/models/taskinstance.py", line 444, in _execute_task
    result = _execute_callable(context=context, **execute_callable_kwargs)
  File "/home/airflow/.local/lib/python3.8/site-packages/airflow/models/taskinstance.py", line 414, in _execute_callable
    return execute_callable(context=context, **execute_callable_kwargs)
  File "/home/airflow/.local/lib/python3.8/site-packages/airflow/decorators/base.py", line 241, in execute
    return_value = super().execute(context)
  File "/home/airflow/.local/lib/python3.8/site-packages/airflow/operators/python.py", line 200, in execute
    return_value = self.execute_callable()
  File "/home/airflow/.local/lib/python3.8/site-packages/airflow/operators/python.py", line 217, in execute_callable
    return self.python_callable(*self.op_args, **self.op_kwargs)
  File "/opt/airflow/dags/pipeline.py", line 64, in data_cleanse
    df = pd.read_csv(csv_file_path)
  File "/home/airflow/.local/lib/python3.8/site-packages/pandas/io/parsers/readers.py", line 912, in read_csv
    return _read(filepath_or_buffer, kwds)
  File "/home/airflow/.local/lib/python3.8/site-packages/pandas/io/parsers/readers.py", line 577, in _read
    parser = TextFileReader(filepath_or_buffer, **kwds)
  File "/home/airflow/.local/lib/python3.8/site-packages/pandas/io/parsers/readers.py", line 1407, in __init__
    self._engine = self._make_engine(f, self.engine)
  File "/home/airflow/.local/lib/python3.8/site-packages/pandas/io/parsers/readers.py", line 1661, in _make_engine
    self.handles = get_handle(
  File "/home/airflow/.local/lib/python3.8/site-packages/pandas/io/common.py", line 716, in get_handle
    ioargs = _get_filepath_or_buffer(
  File "/home/airflow/.local/lib/python3.8/site-packages/pandas/io/common.py", line 456, in _get_filepath_or_buffer
    raise ValueError(msg)
ValueError: Invalid file path or buffer object type: <class 'NoneType'>
[2024-05-01T06:57:49.193+0000] {taskinstance.py:1149} INFO - Marking task as FAILED. dag_id=homework2_data_pipeline_demo, task_id=data_cleanse, execution_date=20240430T205543, start_date=20240501T065748, end_date=20240501T065749
[2024-05-01T06:57:49.210+0000] {standard_task_runner.py:107} ERROR - Failed to execute job 95 for task data_cleanse (Invalid file path or buffer object type: <class 'NoneType'>; 8071)
[2024-05-01T06:57:49.231+0000] {local_task_job_runner.py:234} INFO - Task exited with return code 1
[2024-05-01T06:57:49.262+0000] {taskinstance.py:3312} INFO - 0 downstream tasks scheduled from follow-on schedule check
