[2024-04-30T21:00:30.332+0000] {taskinstance.py:1979} INFO - Dependencies all met for dep_context=non-requeueable deps ti=<TaskInstance: homework2_data_pipeline_demo.data_analysis manual__2024-04-30T20:55:43.518367+00:00 [queued]>
[2024-04-30T21:00:30.343+0000] {taskinstance.py:1979} INFO - Dependencies all met for dep_context=requeueable deps ti=<TaskInstance: homework2_data_pipeline_demo.data_analysis manual__2024-04-30T20:55:43.518367+00:00 [queued]>
[2024-04-30T21:00:30.344+0000] {taskinstance.py:2193} INFO - Starting attempt 1 of 1
[2024-04-30T21:00:30.363+0000] {taskinstance.py:2217} INFO - Executing <Task(_PythonDecoratedOperator): data_analysis> on 2024-04-30 20:55:43.518367+00:00
[2024-04-30T21:00:30.371+0000] {standard_task_runner.py:60} INFO - Started process 6482 to run task
[2024-04-30T21:00:30.375+0000] {standard_task_runner.py:87} INFO - Running: ['***', 'tasks', 'run', 'homework2_data_pipeline_demo', 'data_analysis', 'manual__2024-04-30T20:55:43.518367+00:00', '--job-id', '63', '--raw', '--subdir', 'DAGS_FOLDER/pipeline.py', '--cfg-path', '/tmp/tmpdkej9hxc']
[2024-04-30T21:00:30.377+0000] {standard_task_runner.py:88} INFO - Job 63: Subtask data_analysis
[2024-04-30T21:00:30.450+0000] {task_command.py:423} INFO - Running <TaskInstance: homework2_data_pipeline_demo.data_analysis manual__2024-04-30T20:55:43.518367+00:00 [running]> on host f153e58ecd1c
[2024-04-30T21:00:30.565+0000] {taskinstance.py:2513} INFO - Exporting env vars: AIRFLOW_CTX_DAG_OWNER='***' AIRFLOW_CTX_DAG_ID='homework2_data_pipeline_demo' AIRFLOW_CTX_TASK_ID='data_analysis' AIRFLOW_CTX_EXECUTION_DATE='2024-04-30T20:55:43.518367+00:00' AIRFLOW_CTX_TRY_NUMBER='1' AIRFLOW_CTX_DAG_RUN_ID='manual__2024-04-30T20:55:43.518367+00:00'
[2024-04-30T21:00:30.568+0000] {taskinstance.py:2731} ERROR - Task failed with exception
Traceback (most recent call last):
  File "/home/airflow/.local/lib/python3.8/site-packages/airflow/models/taskinstance.py", line 444, in _execute_task
    result = _execute_callable(context=context, **execute_callable_kwargs)
  File "/home/airflow/.local/lib/python3.8/site-packages/airflow/models/taskinstance.py", line 414, in _execute_callable
    return execute_callable(context=context, **execute_callable_kwargs)
  File "/home/airflow/.local/lib/python3.8/site-packages/airflow/decorators/base.py", line 241, in execute
    return_value = super().execute(context)
  File "/home/airflow/.local/lib/python3.8/site-packages/airflow/operators/python.py", line 200, in execute
    return_value = self.execute_callable()
  File "/home/airflow/.local/lib/python3.8/site-packages/airflow/operators/python.py", line 217, in execute_callable
    return self.python_callable(*self.op_args, **self.op_kwargs)
  File "/opt/airflow/dags/pipeline.py", line 79, in data_analysis
    with open(data_path, "w") as file:
FileNotFoundError: [Errno 2] No such file or directory: '/storage/analysis/1234'
[2024-04-30T21:00:30.582+0000] {taskinstance.py:1149} INFO - Marking task as FAILED. dag_id=homework2_data_pipeline_demo, task_id=data_analysis, execution_date=20240430T205543, start_date=20240430T210030, end_date=20240430T210030
[2024-04-30T21:00:30.597+0000] {standard_task_runner.py:107} ERROR - Failed to execute job 63 for task data_analysis ([Errno 2] No such file or directory: '/storage/analysis/1234'; 6482)
[2024-04-30T21:00:30.628+0000] {local_task_job_runner.py:234} INFO - Task exited with return code 1
[2024-04-30T21:00:30.659+0000] {taskinstance.py:3312} INFO - 0 downstream tasks scheduled from follow-on schedule check
