[2024-05-15T08:33:53.789+0000] {taskinstance.py:1979} INFO - Dependencies all met for dep_context=non-requeueable deps ti=<TaskInstance: homework2_data_pipeline_demo.data_analysis manual__2024-04-30T20:55:51.830154+00:00 [queued]>
[2024-05-15T08:33:53.801+0000] {taskinstance.py:1979} INFO - Dependencies all met for dep_context=requeueable deps ti=<TaskInstance: homework2_data_pipeline_demo.data_analysis manual__2024-04-30T20:55:51.830154+00:00 [queued]>
[2024-05-15T08:33:53.802+0000] {taskinstance.py:2193} INFO - Starting attempt 14 of 14
[2024-05-15T08:33:53.821+0000] {taskinstance.py:2217} INFO - Executing <Task(_PythonDecoratedOperator): data_analysis> on 2024-04-30 20:55:51.830154+00:00
[2024-05-15T08:33:53.829+0000] {standard_task_runner.py:60} INFO - Started process 159 to run task
[2024-05-15T08:33:53.834+0000] {standard_task_runner.py:87} INFO - Running: ['***', 'tasks', 'run', 'homework2_data_pipeline_demo', 'data_analysis', 'manual__2024-04-30T20:55:51.830154+00:00', '--job-id', '175', '--raw', '--subdir', 'DAGS_FOLDER/pipeline.py', '--cfg-path', '/tmp/tmplti8dnis']
[2024-05-15T08:33:53.835+0000] {standard_task_runner.py:88} INFO - Job 175: Subtask data_analysis
[2024-05-15T08:33:53.897+0000] {task_command.py:423} INFO - Running <TaskInstance: homework2_data_pipeline_demo.data_analysis manual__2024-04-30T20:55:51.830154+00:00 [running]> on host f153e58ecd1c
[2024-05-15T08:33:54.004+0000] {taskinstance.py:2513} INFO - Exporting env vars: AIRFLOW_CTX_DAG_OWNER='***' AIRFLOW_CTX_DAG_ID='homework2_data_pipeline_demo' AIRFLOW_CTX_TASK_ID='data_analysis' AIRFLOW_CTX_EXECUTION_DATE='2024-04-30T20:55:51.830154+00:00' AIRFLOW_CTX_TRY_NUMBER='14' AIRFLOW_CTX_DAG_RUN_ID='manual__2024-04-30T20:55:51.830154+00:00'
[2024-05-15T08:33:54.028+0000] {taskinstance.py:2731} ERROR - Task failed with exception
Traceback (most recent call last):
  File "/home/airflow/.local/lib/python3.8/site-packages/pandas/core/indexes/base.py", line 3653, in get_loc
    return self._engine.get_loc(casted_key)
  File "pandas/_libs/index.pyx", line 147, in pandas._libs.index.IndexEngine.get_loc
  File "pandas/_libs/index.pyx", line 176, in pandas._libs.index.IndexEngine.get_loc
  File "pandas/_libs/hashtable_class_helper.pxi", line 7080, in pandas._libs.hashtable.PyObjectHashTable.get_item
  File "pandas/_libs/hashtable_class_helper.pxi", line 7088, in pandas._libs.hashtable.PyObjectHashTable.get_item
KeyError: 'Price'

The above exception was the direct cause of the following exception:

Traceback (most recent call last):
  File "/home/airflow/.local/lib/python3.8/site-packages/airflow/models/taskinstance.py", line 444, in _execute_task
    result = _execute_callable(context=context, **execute_callable_kwargs)
  File "/home/airflow/.local/lib/python3.8/site-packages/airflow/models/taskinstance.py", line 414, in _execute_callable
    return execute_callable(context=context, **execute_callable_kwargs)
  File "/home/airflow/.local/lib/python3.8/site-packages/airflow/decorators/base.py", line 241, in execute
    return_value = super().execute(context)
  File "/home/airflow/.local/lib/python3.8/site-packages/airflow/operators/python.py", line 200, in execute
    return_value = self.execute_callable()
  File "/home/airflow/.local/lib/python3.8/site-packages/airflow/operators/python.py", line 217, in execute_callable
    return self.python_callable(*self.op_args, **self.op_kwargs)
  File "/opt/airflow/dags/pipeline.py", line 115, in data_analysis
    quantitative_results['mean_price'] = df['Price'].mean()
  File "/home/airflow/.local/lib/python3.8/site-packages/pandas/core/frame.py", line 3761, in __getitem__
    indexer = self.columns.get_loc(key)
  File "/home/airflow/.local/lib/python3.8/site-packages/pandas/core/indexes/base.py", line 3655, in get_loc
    raise KeyError(key) from err
KeyError: 'Price'
[2024-05-15T08:33:54.061+0000] {taskinstance.py:1149} INFO - Marking task as FAILED. dag_id=homework2_data_pipeline_demo, task_id=data_analysis, execution_date=20240430T205551, start_date=20240515T083353, end_date=20240515T083354
[2024-05-15T08:33:54.080+0000] {standard_task_runner.py:107} ERROR - Failed to execute job 175 for task data_analysis ('Price'; 159)
[2024-05-15T08:33:54.128+0000] {local_task_job_runner.py:234} INFO - Task exited with return code 1
[2024-05-15T08:33:54.163+0000] {taskinstance.py:3312} INFO - 0 downstream tasks scheduled from follow-on schedule check
