[2024-04-30T20:48:40.659+0000] {taskinstance.py:1979} INFO - Dependencies all met for dep_context=non-requeueable deps ti=<TaskInstance: homework2_data_pipeline_demo.data_cleanse manual__2024-04-30T20:30:41.382358+00:00 [queued]>
[2024-04-30T20:48:40.671+0000] {taskinstance.py:1979} INFO - Dependencies all met for dep_context=requeueable deps ti=<TaskInstance: homework2_data_pipeline_demo.data_cleanse manual__2024-04-30T20:30:41.382358+00:00 [queued]>
[2024-04-30T20:48:40.672+0000] {taskinstance.py:2193} INFO - Starting attempt 4 of 4
[2024-04-30T20:48:40.691+0000] {taskinstance.py:2217} INFO - Executing <Task(_PythonDecoratedOperator): data_cleanse> on 2024-04-30 20:30:41.382358+00:00
[2024-04-30T20:48:40.697+0000] {standard_task_runner.py:60} INFO - Started process 5697 to run task
[2024-04-30T20:48:40.702+0000] {standard_task_runner.py:87} INFO - Running: ['***', 'tasks', 'run', 'homework2_data_pipeline_demo', 'data_cleanse', 'manual__2024-04-30T20:30:41.382358+00:00', '--job-id', '40', '--raw', '--subdir', 'DAGS_FOLDER/pipeline.py', '--cfg-path', '/tmp/tmpvp2vs92f']
[2024-04-30T20:48:40.704+0000] {standard_task_runner.py:88} INFO - Job 40: Subtask data_cleanse
[2024-04-30T20:48:40.766+0000] {task_command.py:423} INFO - Running <TaskInstance: homework2_data_pipeline_demo.data_cleanse manual__2024-04-30T20:30:41.382358+00:00 [running]> on host f153e58ecd1c
[2024-04-30T20:48:40.873+0000] {taskinstance.py:2513} INFO - Exporting env vars: AIRFLOW_CTX_DAG_OWNER='***' AIRFLOW_CTX_DAG_ID='homework2_data_pipeline_demo' AIRFLOW_CTX_TASK_ID='data_cleanse' AIRFLOW_CTX_EXECUTION_DATE='2024-04-30T20:30:41.382358+00:00' AIRFLOW_CTX_TRY_NUMBER='4' AIRFLOW_CTX_DAG_RUN_ID='manual__2024-04-30T20:30:41.382358+00:00'
[2024-04-30T20:48:40.888+0000] {taskinstance.py:2731} ERROR - Task failed with exception
Traceback (most recent call last):
  File "/home/airflow/.local/lib/python3.8/site-packages/pandas/core/indexes/base.py", line 3653, in get_loc
    return self._engine.get_loc(casted_key)
  File "pandas/_libs/index.pyx", line 147, in pandas._libs.index.IndexEngine.get_loc
  File "pandas/_libs/index.pyx", line 176, in pandas._libs.index.IndexEngine.get_loc
  File "pandas/_libs/hashtable_class_helper.pxi", line 7080, in pandas._libs.hashtable.PyObjectHashTable.get_item
  File "pandas/_libs/hashtable_class_helper.pxi", line 7088, in pandas._libs.hashtable.PyObjectHashTable.get_item
KeyError: 'RegionName'

The above exception was the direct cause of the following exception:

Traceback (most recent call last):
  File "/home/airflow/.local/lib/python3.8/site-packages/airflow/models/taskinstance.py", line 444, in _execute_task
    result = _execute_callable(context=context, **execute_callable_kwargs)
  File "/home/airflow/.local/lib/python3.8/site-packages/airflow/models/taskinstance.py", line 414, in _execute_callable
    return execute_callable(context=context, **execute_callable_kwargs)
  File "/home/airflow/.local/lib/python3.8/site-packages/airflow/decorators/base.py", line 241, in execute
    return_value = super().execute(context)
  File "/home/airflow/.local/lib/python3.8/site-packages/airflow/operators/python.py", line 200, in execute
    return_value = self.execute_callable()
  File "/home/airflow/.local/lib/python3.8/site-packages/airflow/operators/python.py", line 217, in execute_callable
    return self.python_callable(*self.op_args, **self.op_kwargs)
  File "/opt/airflow/dags/pipeline.py", line 58, in data_cleanse
    df = df[df['RegionName'].str.contains('CA', na=False)]
  File "/home/airflow/.local/lib/python3.8/site-packages/pandas/core/frame.py", line 3761, in __getitem__
    indexer = self.columns.get_loc(key)
  File "/home/airflow/.local/lib/python3.8/site-packages/pandas/core/indexes/base.py", line 3655, in get_loc
    raise KeyError(key) from err
KeyError: 'RegionName'
[2024-04-30T20:48:40.906+0000] {taskinstance.py:1149} INFO - Marking task as FAILED. dag_id=homework2_data_pipeline_demo, task_id=data_cleanse, execution_date=20240430T203041, start_date=20240430T204840, end_date=20240430T204840
[2024-04-30T20:48:40.921+0000] {standard_task_runner.py:107} ERROR - Failed to execute job 40 for task data_cleanse ('RegionName'; 5697)
[2024-04-30T20:48:40.955+0000] {local_task_job_runner.py:234} INFO - Task exited with return code 1
[2024-04-30T20:48:40.984+0000] {taskinstance.py:3312} INFO - 0 downstream tasks scheduled from follow-on schedule check
